2022-10-05 22:05:29,645 ERROR: Exception on /homepage [GET] [in /home/duonglieumoc/OneDrive/python_program/website/venvy/lib/python3.10/site-packages/flask/app.py:1741]
Traceback (most recent call last):
  File "/home/duonglieumoc/OneDrive/python_program/website/venvy/lib/python3.10/site-packages/flask/app.py", line 2525, in wsgi_app
    response = self.full_dispatch_request()
  File "/home/duonglieumoc/OneDrive/python_program/website/venvy/lib/python3.10/site-packages/flask/app.py", line 1822, in full_dispatch_request
    rv = self.handle_user_exception(e)
  File "/home/duonglieumoc/OneDrive/python_program/website/venvy/lib/python3.10/site-packages/flask/app.py", line 1820, in full_dispatch_request
    rv = self.dispatch_request()
  File "/home/duonglieumoc/OneDrive/python_program/website/venvy/lib/python3.10/site-packages/flask/app.py", line 1796, in dispatch_request
    return self.ensure_sync(self.view_functions[rule.endpoint])(**view_args)
  File "/home/duonglieumoc/OneDrive/python_program/website/venvy/lib/python3.10/site-packages/flask_login/utils.py", line 290, in decorated_view
    return current_app.ensure_sync(func)(*args, **kwargs)
  File "/home/duonglieumoc/OneDrive/python_program/website/app/main/routes.py", line 28, in homepage
    return render_template('home.html')
  File "/home/duonglieumoc/OneDrive/python_program/website/venvy/lib/python3.10/site-packages/flask/templating.py", line 147, in render_template
    return _render(app, template, context)
  File "/home/duonglieumoc/OneDrive/python_program/website/venvy/lib/python3.10/site-packages/flask/templating.py", line 130, in _render
    rv = template.render(context)
  File "/home/duonglieumoc/OneDrive/python_program/website/venvy/lib/python3.10/site-packages/jinja2/environment.py", line 1301, in render
    self.environment.handle_exception()
  File "/home/duonglieumoc/OneDrive/python_program/website/venvy/lib/python3.10/site-packages/jinja2/environment.py", line 936, in handle_exception
    raise rewrite_traceback_stack(source=source)
  File "/home/duonglieumoc/OneDrive/python_program/website/app/templates/home.html", line 1, in top-level template code
    {% extends "base.html" %} {% block content %}
  File "/home/duonglieumoc/OneDrive/python_program/website/app/templates/base.html", line 27, in top-level template code
    <a href="{{ url_for('auth.signup') }}" class="navbar-item">
  File "/home/duonglieumoc/OneDrive/python_program/website/venvy/lib/python3.10/site-packages/flask/app.py", line 2031, in url_for
    return self.handle_url_build_error(error, endpoint, values)
  File "/home/duonglieumoc/OneDrive/python_program/website/venvy/lib/python3.10/site-packages/flask/app.py", line 2020, in url_for
    rv = url_adapter.build(  # type: ignore[union-attr]
  File "/home/duonglieumoc/OneDrive/python_program/website/venvy/lib/python3.10/site-packages/werkzeug/routing/map.py", line 917, in build
    raise BuildError(endpoint, values, method, self)
werkzeug.routing.exceptions.BuildError: Could not build url for endpoint 'auth.signup'. Did you mean 'auth.login' instead?
2022-10-05 22:06:17,653 INFO: ANACOM logs [in /home/duonglieumoc/OneDrive/python_program/website/app/__init__.py:78]
2022-10-05 22:06:38,521 INFO: ANACOM logs [in /home/duonglieumoc/OneDrive/python_program/website/app/__init__.py:78]
2022-10-05 22:21:21,182 INFO: ANACOM logs [in /home/duonglieumoc/OneDrive/python_program/website/app/__init__.py:78]
2022-10-05 22:24:59,099 INFO: ANACOM logs [in /home/duonglieumoc/OneDrive/python_program/website/app/__init__.py:78]
2022-10-05 22:27:01,914 INFO: ANACOM logs [in /home/duonglieumoc/OneDrive/python_program/website/app/__init__.py:78]
2022-10-05 22:31:32,792 INFO: ANACOM logs [in /home/duonglieumoc/OneDrive/python_program/website/app/__init__.py:78]
2022-10-05 22:42:49,296 INFO: ANACOM logs [in /home/duonglieumoc/OneDrive/python_program/website/app/__init__.py:78]
